<?xml version="1.0" encoding="UTF-8"?>
<robot name="bipedal">
  <joint name="joint_bipedal-Imu_Sensor" type="fixed">
    <origin xyz="0.00112 -0.00352 0.0335484" rpy="0. 0. 0."/>
    <parent link="body"/>
    <child link="Imu_Sensor"/>
  </joint>
  <joint name="l_arm_joint" type="revolute">
    <origin xyz="0. 0.052 -0.0466" rpy="-1.5707964 -1.5707964 0. "/>
    <parent link="l_hip"/>
    <child link="l_arm"/>
    <axis xyz="0. 0. 1."/>
    <limit lower="-1.5707963" upper="1.5707963" effort="9.0" velocity="0."/>
  </joint>
  <joint name="l_foot_joint" type="revolute">
    <origin xyz="0.0050727 0.190988 -0.0065 " rpy="3.1415925 0.0 1.6491442"/>
    <parent link="l_forearm"/>
    <child link="l_foot"/>
    <axis xyz="0. 0. 1."/>
    <limit lower="-1.2217305" upper="1.2217305" effort="9.0" velocity="0."/>
  </joint>
  <joint name="l_hip_joint" type="revolute">
    <origin xyz="0.05014 -0.04636 -0.00849" rpy="1.5707964 1.5707964 0. "/>
    <parent link="body"/>
    <child link="l_hip"/>
    <axis xyz="0. 0. 1."/>
    <limit lower="-0.4363323" upper="0.5235988" effort="9.0" velocity="0."/>
  </joint>
  <joint name="l_knee_joint" type="revolute">
    <origin xyz="-0.11573 0.03173 0. " rpy="0.0 0.0 -0.4007102"/>
    <parent link="l_arm"/>
    <child link="l_forearm"/>
    <axis xyz="0. 0. 1."/>
    <limit lower="-0.8726646" upper="1.7453293" effort="9.0" velocity="0."/>
  </joint>
  <joint name="r_arm_joint" type="revolute">
    <origin xyz="0. 0.05201 0.04661" rpy="1.5707964 1.5707964 0. "/>
    <parent link="r_hip"/>
    <child link="r_arm"/>
    <axis xyz="0. 0. 1."/>
    <limit lower="-1.5707963" upper="1.5707963" effort="9.0" velocity="0."/>
  </joint>
  <joint name="r_foot_joint" type="revolute">
    <origin xyz="0.004207 0.1910052 0.0065 " rpy="3.1415927 0. 1.6536472"/>
    <parent link="r_forearm"/>
    <child link="r_foot"/>
    <axis xyz="0. 0. 1."/>
    <limit lower="-1.2217305" upper="1.2217305" effort="9.0" velocity="0."/>
  </joint>
  <joint name="r_hip_joint" type="revolute">
    <origin xyz="-0.04985 -0.04637 -0.00849" rpy="-1.5707964 1.5707964 0. "/>
    <parent link="body"/>
    <child link="r_hip"/>
    <axis xyz="0. 0. 1."/>
    <limit lower="-0.4363323" upper="0.5235988" effort="9.0" velocity="0."/>
  </joint>
  <joint name="r_knee_joint" type="revolute">
    <origin xyz="-0.11566 0.03196 -0. " rpy="0. 0. -0.402665"/>
    <parent link="r_arm"/>
    <child link="r_forearm"/>
    <axis xyz="0. 0. 1."/>
    <limit lower="-0.8726646" upper="1.7453293" effort="9.0" velocity="0."/>
  </joint>
  <link name="Imu_Sensor"/>
  <link name="body">
    <inertial>
      <origin xyz="0.00184695 -0.00867721 -0.01611131" rpy="0. 0. 0."/>
      <mass value="1.94701706"/>
      <inertia ixx="0.00884225" ixy="-0.00009647" ixz="-0.00021269" iyy="-0.00009647" iyz="0.0003109" izz="0.00908713"/>
    </inertial>
    <collision>
      <origin xyz="0.00056 0.0104835 -0.011461 " rpy="0. 0. 0."/>
      <geometry>
        <box size="0.1160978 0.2033129 0.13758 "/>
      </geometry>
    </collision>
    <visual>
      <origin xyz="0.00056 -0.00176 0.00059" rpy="0. 0. 0."/>
      <geometry>
        <mesh filename="meshes/tattu_4500_mah.obj" scale="1. 1. 1."/>
      </geometry>
    </visual>
    <visual>
      <origin xyz="0.00056 -0.00176 0.00959" rpy="0. 0. 0."/>
      <geometry>
        <mesh filename="meshes/nucleo_l476rg.obj" scale="1. 1. 1."/>
      </geometry>
    </visual>
    <visual>
      <origin xyz="0. 0. 0." rpy="0. 0. 0."/>
      <geometry>
        <mesh filename="meshes/kria_kv_260.obj" scale="1. 1. 1."/>
      </geometry>
    </visual>
    <visual>
      <origin xyz="0.0000028 -0.0000024 -0.0000023" rpy="0. 0. 0."/>
      <geometry>
        <mesh filename="meshes/printed_body_parts.obj" scale="1. 1. 1."/>
      </geometry>
    </visual>
    <visual>
      <origin xyz="-0.1056196 -0.0789026 -0.03137 " rpy="0. 0. 0.0022334"/>
      <geometry>
        <mesh filename="meshes/ak60_6.obj" scale="1. 1. 1."/>
      </geometry>
    </visual>
    <visual>
      <origin xyz="-0.00594 -0.07868 -0.03137" rpy="0. 0. 0.0022334"/>
      <geometry>
        <mesh filename="meshes/ak60_6.obj" scale="1. 1. 1."/>
      </geometry>
    </visual>
  </link>
  <link name="l_arm">
    <inertial>
      <origin xyz="0.1187287 0.0582346 -0.0239836" rpy="0. 0. 0."/>
      <mass value="0.8257222"/>
      <inertia ixx="0.0035457" ixy="0.0000002" ixz="-0.0000004" iyy="0.00069" iyz="-0." izz="0.0030306"/>
    </inertial>
    <visual>
      <origin xyz="0.00024 -0.00849 -0.10214" rpy="1.5707964 -1.5707964 0. "/>
      <geometry>
        <mesh filename="meshes/l_arm.obj" scale="1. 1. 1."/>
      </geometry>
    </visual>
    <collision>
      <origin xyz="-0.059147 0.0160712 0.01887 " rpy="1.293073 -1.5707964 0. "/>
      <geometry>
        <box size="0.0455878 0.1951695 0.0797575"/>
      </geometry>
    </collision>
  </link>
  <link name="l_foot">
    <inertial>
      <origin xyz="0. 0. 0." rpy="0. 0. 0."/>
      <mass value="0.04745"/>
      <inertia ixx="0.001" ixy="0." ixz="0." iyy="0.001" iyz="0." izz="0.001"/>
    </inertial>
    <visual>
      <origin xyz="-0.1914131 0.102733 0.09564 " rpy="-2.8192303 1.5707964 0. "/>
      <geometry>
        <mesh filename="meshes/foot.obj" scale="1. 1. 1."/>
      </geometry>
    </visual>
    <collision>
      <origin xyz="0.0277056 0.0127352 0.01143 " rpy="-2.8192303 1.5707964 0. "/>
      <geometry>
        <box size="0.036 0.1227169 0.0099255"/>
      </geometry>
    </collision>
  </link>
  <link name="l_forearm">
    <inertial>
      <origin xyz="0.085199 0.0737789 -0.1413163" rpy="0. 0. 0."/>
      <mass value="0.1135116"/>
      <inertia ixx="0.0006658" ixy="0." ixz="0." iyy="0.0005389" iyz="0." izz="0.0001361"/>
    </inertial>
    <visual>
      <origin xyz="0.1224721 0.0082028 -0.10214 " rpy="1.9715065 -1.5707963 0. "/>
      <geometry>
        <mesh filename="meshes/l_forearm.obj" scale="1. 1. 1."/>
      </geometry>
    </visual>
    <collision>
      <origin xyz="-0.0030734 0.0774761 -0.01793 " rpy="1.5765638 -1.5707963 0. "/>
      <geometry>
        <box size="0.0174227 0.0354954 0.186567 "/>
      </geometry>
    </collision>
  </link>
  <link name="r_foot">
    <inertial>
      <origin xyz="0. 0. 0." rpy="0. 0. 0."/>
      <mass value="0.04745"/>
      <inertia ixx="0.001" ixy="0." ixz="0." iyy="0.001" iyz="0." izz="0.001"/>
    </inertial>
    <visual> 
      <origin xyz="-0.1914131 0.102733 -0.09564" rpy="-2.8217785 1.5707964 0. "/>
      <geometry>
        <mesh filename="meshes/foot.obj" scale="-1. 1. 1."/>
      </geometry>
    </visual>
    <collision>
      <origin xyz="0.0273844 0.0133017 -0.0111505" rpy="-2.8217785 1.5707964 0. "/>
      <geometry>
        <box size="0.036 0.1227169 0.0099255"/>
      </geometry>
    </collision>
  </link>
  <link name="r_forearm">
    <inertial>
      <origin xyz="-0.0849117 0.073974 -0.1416498" rpy="0. 0. 0."/>
      <mass value="0.1135116"/>
      <inertia ixx="0.0006658" ixy="0." ixz="0." iyy="0.0005401" iyz="0." izz="0.0001349"/>
    </inertial>
    <visual>
      <origin xyz="0.1224815 0.0082031 0.10186 " rpy="1.9734613 -1.5707964 0. "/>
      <geometry>
        <mesh filename="meshes/r_forearm.obj" scale="1. 1. 1."/>
      </geometry>
    </visual>
    <collision>
      <origin xyz="-0.0031991 0.0772309 0.01765 " rpy="1.5785186 -1.5707963 0. "/>
      <geometry>
        <box size="0.0174227 0.0354954 0.186567 "/>
      </geometry>
    </collision>
  </link>
  <link name="l_hip">
    <inertial>
      <origin xyz="0.01698 0.06743 0. " rpy="0. 0. 0."/>
      <mass value="0.07053"/>
      <inertia ixx="0.0001481" ixy="0." ixz="0." iyy="0.0000254" iyz="0." izz="0.0001597"/>
    </inertial>
    <visual>
      <origin xyz="0. -0. 0." rpy="-1.5707964 0. 3.1415927"/>
      <geometry>
        <mesh filename="meshes/hip.obj" scale="1. 1. 1."/>
      </geometry>
    </visual>
  </link>
  <link name="r_arm">
    <inertial>
      <origin xyz="-0.1182537 0.0581932 -0.0240374" rpy="0. 0. 0."/>
      <mass value="0.8423222"/>
      <inertia ixx="0.0036149" ixy="0.0000002" ixz="0." iyy="0.0007136" iyz="0." izz="0.003081"/>
    </inertial>
    <visual>
      <origin xyz="0.00024 -0.00849 0.10186" rpy="1.5707964 -1.5707964 0. "/>
      <geometry>
        <mesh filename="meshes/r_arm.obj" scale="1. 1. 1."/>
      </geometry>
    </visual>
    <collision>
      <origin xyz="-0.059147 0.0160712 -0.0191464" rpy="1.293073 -1.5707964 0. "/>
      <geometry>
        <box size="0.0455878 0.1951695 0.0797575"/>
      </geometry>
    </collision>
  </link>
  <link name="r_hip">
    <inertial>
      <origin xyz="-0.01698 0.06743 0.000001" rpy="0. 0. 0."/>
      <mass value="0.07053"/>
      <inertia ixx="0.0001481" ixy="0." ixz="0." iyy="0.0000254" iyz="0." izz="0.0001597"/>
    </inertial>
    <visual>
      <origin xyz="0. 0.00001 0.00001" rpy="1.5707964 0. 0. "/>
      <geometry>
        <mesh filename="meshes/hip.obj" scale="1. 1. 1."/>
      </geometry>
    </visual>
  </link>
</robot>
